Traceback (most recent call last):
  File "/root/lanyun-tmp/SAFE/main_finetune.py", line 486, in <module>
    main(args)
  File "/root/lanyun-tmp/SAFE/main_finetune.py", line 193, in main
    utils.init_distributed_mode(args)
  File "/root/lanyun-tmp/SAFE/utils/utils.py", line 342, in init_distributed_mode
    torch.cuda.set_device(args.gpu)
  File "/root/miniconda/lib/python3.10/site-packages/torch/cuda/__init__.py", line 408, in set_device
    torch._C._cuda_setDevice(device)
  File "/root/miniconda/lib/python3.10/site-packages/torch/cuda/__init__.py", line 302, in _lazy_init
    torch._C._cuda_init()
RuntimeError: Found no NVIDIA driver on your system. Please check that you have an NVIDIA GPU and installed a driver from http://www.nvidia.com/Download/index.aspx
[2025-05-13 18:34:42,966] torch.distributed.elastic.multiprocessing.api: [ERROR] failed (exitcode: 1) local_rank: 0 (pid: 10621) of binary: /root/miniconda/bin/python
Traceback (most recent call last):
  File "/root/miniconda/bin/torchrun", line 8, in <module>
    sys.exit(main())
  File "/root/miniconda/lib/python3.10/site-packages/torch/distributed/elastic/multiprocessing/errors/__init__.py", line 347, in wrapper
    return f(*args, **kwargs)
  File "/root/miniconda/lib/python3.10/site-packages/torch/distributed/run.py", line 812, in main
    run(args)
  File "/root/miniconda/lib/python3.10/site-packages/torch/distributed/run.py", line 803, in run
    elastic_launch(
  File "/root/miniconda/lib/python3.10/site-packages/torch/distributed/launcher/api.py", line 135, in __call__
    return launch_agent(self._config, self._entrypoint, list(args))
  File "/root/miniconda/lib/python3.10/site-packages/torch/distributed/launcher/api.py", line 268, in launch_agent
    raise ChildFailedError(
torch.distributed.elastic.multiprocessing.errors.ChildFailedError: 
============================================================
main_finetune.py FAILED
------------------------------------------------------------
Failures:
  <NO_OTHER_FAILURES>
------------------------------------------------------------
Root Cause (first observed failure):
[0]:
  time      : 2025-05-13_18:34:42
  host      : 8d8d1adbe08b
  rank      : 0 (local_rank: 0)
  exitcode  : 1 (pid: 10621)
  error_file: <N/A>
  traceback : To enable traceback see: https://pytorch.org/docs/stable/elastic/errors.html
============================================================
